<?xml version="1.0" encoding="UTF-8"?>
<testsuite name="ExamTest" tests="23" skipped="0" failures="9" errors="0" timestamp="2022-06-16T03:19:03" hostname="Achmads-MacBook-Pro.local" time="0.044">
  <properties/>
  <testcase name="[Latihan 1] - 2 is odd number" classname="ExamTest" time="0.014"/>
  <testcase name="[Latihan 1] - 6 is odd number" classname="ExamTest" time="0.001"/>
  <testcase name="[Latihan 1] - 7 is not odd number" classname="ExamTest" time="0.001"/>
  <testcase name="[Latihan 1] - 1 is not odd number" classname="ExamTest" time="0.0"/>
  <testcase name="[Latihan 1] - result function sould be return expected value" classname="ExamTest" time="0.001"/>
  <testcase name="[Latihan 2] - calculate result should be return 54" classname="ExamTest" time="0.001"/>
  <testcase name="[Latihan 2] - calculate result should be return 103" classname="ExamTest" time="0.001"/>
  <testcase name="[Latihan 2] - result function should be return expected value" classname="ExamTest" time="0.001"/>
  <testcase name="[Latihan 3] - checkType should be return Int when passing param is `50`" classname="ExamTest" time="0.001"/>
  <testcase name="[Latihan 3] - checkType should be return String when passing param is `Dicoding Indonesia`" classname="ExamTest" time="0.001"/>
  <testcase name="[Latihan 3] - checkType should be return Double when passing param is `1.0`" classname="ExamTest" time="0.001"/>
  <testcase name="[Latihan 3] - checkType should be return List when passing param is `listOf&lt;Any&gt;`" classname="ExamTest" time="0.0"/>
  <testcase name="[Latihan 3] - checkType should be return Map when passing param is `mapOf&lt;Any, Any&gt;`" classname="ExamTest" time="0.0"/>
  <testcase name="[Latihan 4] - vehicle function should be return Map" classname="ExamTest" time="0.001"/>
  <testcase name="[Latihan 4] - type should be motorcycle" classname="ExamTest" time="0.004">
    <failure message="org.opentest4j.AssertionFailedError: expected: &lt;true&gt; but was: &lt;false&gt;" type="org.opentest4j.AssertionFailedError">org.opentest4j.AssertionFailedError: expected: &lt;true&gt; but was: &lt;false&gt;
	at org.junit.jupiter.api.AssertionUtils.fail(AssertionUtils.java:55)
	at org.junit.jupiter.api.AssertTrue.assertTrue(AssertTrue.java:40)
	at org.junit.jupiter.api.AssertTrue.assertTrue(AssertTrue.java:35)
	at org.junit.jupiter.api.Assertions.assertTrue(Assertions.java:179)
	at ExamTest$1$1$4$2.invoke(ExamTest.kt:105)
	at ExamTest$1$1$4$2.invoke(ExamTest.kt:103)
	at org.spekframework.spek2.runtime.scope.TestScopeImpl.execute(scopes.kt:136)
	at org.spekframework.spek2.runtime.Executor$execute$result$2$exception$1$job$1.invokeSuspend(Executor.kt:84)
	at kotlin.coroutines.jvm.internal.BaseContinuationImpl.resumeWith(ContinuationImpl.kt:33)
	at kotlinx.coroutines.DispatchedTask.run(DispatchedTask.kt:106)
	at kotlinx.coroutines.EventLoopImplBase.processNextEvent(EventLoop.common.kt:279)
	at kotlinx.coroutines.BlockingCoroutine.joinBlocking(Builders.kt:85)
	at kotlinx.coroutines.BuildersKt__BuildersKt.runBlocking(Builders.kt:59)
	at kotlinx.coroutines.BuildersKt.runBlocking(Unknown Source)
	at kotlinx.coroutines.BuildersKt__BuildersKt.runBlocking$default(Builders.kt:38)
	at kotlinx.coroutines.BuildersKt.runBlocking$default(Unknown Source)
	at org.spekframework.spek2.runtime.TaskRunner$runTask$1.run(executors.kt:26)
	at java.util.concurrent.Executors$RunnableAdapter.call(Executors.java:511)
	at java.util.concurrent.FutureTask.run(FutureTask.java:266)
	at java.util.concurrent.ThreadPoolExecutor.runWorker(ThreadPoolExecutor.java:1149)
	at java.util.concurrent.ThreadPoolExecutor$Worker.run(ThreadPoolExecutor.java:624)
	at java.lang.Thread.run(Thread.java:748)
</failure>
  </testcase>
  <testcase name="[Latihan 4] - maxSpeed should be 230Km/s" classname="ExamTest" time="0.001">
    <failure message="org.opentest4j.AssertionFailedError: expected: &lt;true&gt; but was: &lt;false&gt;" type="org.opentest4j.AssertionFailedError">org.opentest4j.AssertionFailedError: expected: &lt;true&gt; but was: &lt;false&gt;
	at org.junit.jupiter.api.AssertionUtils.fail(AssertionUtils.java:55)
	at org.junit.jupiter.api.AssertTrue.assertTrue(AssertTrue.java:40)
	at org.junit.jupiter.api.AssertTrue.assertTrue(AssertTrue.java:35)
	at org.junit.jupiter.api.Assertions.assertTrue(Assertions.java:179)
	at ExamTest$1$1$4$3.invoke(ExamTest.kt:111)
	at ExamTest$1$1$4$3.invoke(ExamTest.kt:109)
	at org.spekframework.spek2.runtime.scope.TestScopeImpl.execute(scopes.kt:136)
	at org.spekframework.spek2.runtime.Executor$execute$result$2$exception$1$job$1.invokeSuspend(Executor.kt:84)
	at kotlin.coroutines.jvm.internal.BaseContinuationImpl.resumeWith(ContinuationImpl.kt:33)
	at kotlinx.coroutines.DispatchedTask.run(DispatchedTask.kt:106)
	at kotlinx.coroutines.EventLoopImplBase.processNextEvent(EventLoop.common.kt:279)
	at kotlinx.coroutines.BlockingCoroutine.joinBlocking(Builders.kt:85)
	at kotlinx.coroutines.BuildersKt__BuildersKt.runBlocking(Builders.kt:59)
	at kotlinx.coroutines.BuildersKt.runBlocking(Unknown Source)
	at kotlinx.coroutines.BuildersKt__BuildersKt.runBlocking$default(Builders.kt:38)
	at kotlinx.coroutines.BuildersKt.runBlocking$default(Unknown Source)
	at org.spekframework.spek2.runtime.TaskRunner$runTask$1.run(executors.kt:26)
	at java.util.concurrent.Executors$RunnableAdapter.call(Executors.java:511)
	at java.util.concurrent.FutureTask.run(FutureTask.java:266)
	at java.util.concurrent.ThreadPoolExecutor.runWorker(ThreadPoolExecutor.java:1149)
	at java.util.concurrent.ThreadPoolExecutor$Worker.run(ThreadPoolExecutor.java:624)
	at java.lang.Thread.run(Thread.java:748)
</failure>
  </testcase>
  <testcase name="[Latihan 4] - maxTank should be 100Ltr" classname="ExamTest" time="0.0">
    <failure message="org.opentest4j.AssertionFailedError: expected: &lt;true&gt; but was: &lt;false&gt;" type="org.opentest4j.AssertionFailedError">org.opentest4j.AssertionFailedError: expected: &lt;true&gt; but was: &lt;false&gt;
	at org.junit.jupiter.api.AssertionUtils.fail(AssertionUtils.java:55)
	at org.junit.jupiter.api.AssertTrue.assertTrue(AssertTrue.java:40)
	at org.junit.jupiter.api.AssertTrue.assertTrue(AssertTrue.java:35)
	at org.junit.jupiter.api.Assertions.assertTrue(Assertions.java:179)
	at ExamTest$1$1$4$4.invoke(ExamTest.kt:117)
	at ExamTest$1$1$4$4.invoke(ExamTest.kt:115)
	at org.spekframework.spek2.runtime.scope.TestScopeImpl.execute(scopes.kt:136)
	at org.spekframework.spek2.runtime.Executor$execute$result$2$exception$1$job$1.invokeSuspend(Executor.kt:84)
	at kotlin.coroutines.jvm.internal.BaseContinuationImpl.resumeWith(ContinuationImpl.kt:33)
	at kotlinx.coroutines.DispatchedTask.run(DispatchedTask.kt:106)
	at kotlinx.coroutines.EventLoopImplBase.processNextEvent(EventLoop.common.kt:279)
	at kotlinx.coroutines.BlockingCoroutine.joinBlocking(Builders.kt:85)
	at kotlinx.coroutines.BuildersKt__BuildersKt.runBlocking(Builders.kt:59)
	at kotlinx.coroutines.BuildersKt.runBlocking(Unknown Source)
	at kotlinx.coroutines.BuildersKt__BuildersKt.runBlocking$default(Builders.kt:38)
	at kotlinx.coroutines.BuildersKt.runBlocking$default(Unknown Source)
	at org.spekframework.spek2.runtime.TaskRunner$runTask$1.run(executors.kt:26)
	at java.util.concurrent.Executors$RunnableAdapter.call(Executors.java:511)
	at java.util.concurrent.FutureTask.run(FutureTask.java:266)
	at java.util.concurrent.ThreadPoolExecutor.runWorker(ThreadPoolExecutor.java:1149)
	at java.util.concurrent.ThreadPoolExecutor$Worker.run(ThreadPoolExecutor.java:624)
	at java.lang.Thread.run(Thread.java:748)
</failure>
  </testcase>
  <testcase name="[Latihan 5] - execution time of sum function should be more than 3s" classname="ExamTest" time="0.001">
    <failure message="org.opentest4j.AssertionFailedError: expected: &lt;true&gt; but was: &lt;false&gt;" type="org.opentest4j.AssertionFailedError">org.opentest4j.AssertionFailedError: expected: &lt;true&gt; but was: &lt;false&gt;
	at org.junit.jupiter.api.AssertionUtils.fail(AssertionUtils.java:55)
	at org.junit.jupiter.api.AssertTrue.assertTrue(AssertTrue.java:40)
	at org.junit.jupiter.api.AssertTrue.assertTrue(AssertTrue.java:35)
	at org.junit.jupiter.api.Assertions.assertTrue(Assertions.java:179)
	at ExamTest$1$1$5$1$1.invokeSuspend(ExamTest.kt:129)
	at kotlin.coroutines.jvm.internal.BaseContinuationImpl.resumeWith(ContinuationImpl.kt:33)
	at kotlinx.coroutines.DispatchedTask.run(DispatchedTask.kt:106)
	at kotlinx.coroutines.EventLoopImplBase.processNextEvent(EventLoop.common.kt:279)
	at kotlinx.coroutines.BlockingCoroutine.joinBlocking(Builders.kt:85)
	at kotlinx.coroutines.BuildersKt__BuildersKt.runBlocking(Builders.kt:59)
	at kotlinx.coroutines.BuildersKt.runBlocking(Unknown Source)
	at kotlinx.coroutines.BuildersKt__BuildersKt.runBlocking$default(Builders.kt:38)
	at kotlinx.coroutines.BuildersKt.runBlocking$default(Unknown Source)
	at ExamTest$1$1$5$1.invoke(ExamTest.kt:124)
	at ExamTest$1$1$5$1.invoke(ExamTest.kt:123)
	at org.spekframework.spek2.runtime.scope.TestScopeImpl.execute(scopes.kt:136)
	at org.spekframework.spek2.runtime.Executor$execute$result$2$exception$1$job$1.invokeSuspend(Executor.kt:84)
	at kotlin.coroutines.jvm.internal.BaseContinuationImpl.resumeWith(ContinuationImpl.kt:33)
	at kotlinx.coroutines.DispatchedTask.run(DispatchedTask.kt:106)
	at kotlinx.coroutines.EventLoopImplBase.processNextEvent(EventLoop.common.kt:279)
	at kotlinx.coroutines.BlockingCoroutine.joinBlocking(Builders.kt:85)
	at kotlinx.coroutines.BuildersKt__BuildersKt.runBlocking(Builders.kt:59)
	at kotlinx.coroutines.BuildersKt.runBlocking(Unknown Source)
	at kotlinx.coroutines.BuildersKt__BuildersKt.runBlocking$default(Builders.kt:38)
	at kotlinx.coroutines.BuildersKt.runBlocking$default(Unknown Source)
	at org.spekframework.spek2.runtime.TaskRunner$runTask$1.run(executors.kt:26)
	at java.util.concurrent.Executors$RunnableAdapter.call(Executors.java:511)
	at java.util.concurrent.FutureTask.run(FutureTask.java:266)
	at java.util.concurrent.ThreadPoolExecutor.runWorker(ThreadPoolExecutor.java:1149)
	at java.util.concurrent.ThreadPoolExecutor$Worker.run(ThreadPoolExecutor.java:624)
	at java.lang.Thread.run(Thread.java:748)
</failure>
  </testcase>
  <testcase name="[Latihan 5] - sum function should be return 10 if valueA is 5 and valueB is 5" classname="ExamTest" time="0.003">
    <failure message="org.opentest4j.AssertionFailedError: expected: &lt;true&gt; but was: &lt;false&gt;" type="org.opentest4j.AssertionFailedError">org.opentest4j.AssertionFailedError: expected: &lt;true&gt; but was: &lt;false&gt;
	at org.junit.jupiter.api.AssertionUtils.fail(AssertionUtils.java:55)
	at org.junit.jupiter.api.AssertTrue.assertTrue(AssertTrue.java:40)
	at org.junit.jupiter.api.AssertTrue.assertTrue(AssertTrue.java:35)
	at org.junit.jupiter.api.Assertions.assertTrue(Assertions.java:179)
	at ExamTest$1$1$5$2$1.invokeSuspend(ExamTest.kt:136)
	at kotlin.coroutines.jvm.internal.BaseContinuationImpl.resumeWith(ContinuationImpl.kt:33)
	at kotlinx.coroutines.DispatchedTask.run(DispatchedTask.kt:106)
	at kotlinx.coroutines.EventLoopImplBase.processNextEvent(EventLoop.common.kt:279)
	at kotlinx.coroutines.BlockingCoroutine.joinBlocking(Builders.kt:85)
	at kotlinx.coroutines.BuildersKt__BuildersKt.runBlocking(Builders.kt:59)
	at kotlinx.coroutines.BuildersKt.runBlocking(Unknown Source)
	at kotlinx.coroutines.BuildersKt__BuildersKt.runBlocking$default(Builders.kt:38)
	at kotlinx.coroutines.BuildersKt.runBlocking$default(Unknown Source)
	at ExamTest$1$1$5$2.invoke(ExamTest.kt:134)
	at ExamTest$1$1$5$2.invoke(ExamTest.kt:133)
	at org.spekframework.spek2.runtime.scope.TestScopeImpl.execute(scopes.kt:136)
	at org.spekframework.spek2.runtime.Executor$execute$result$2$exception$1$job$1.invokeSuspend(Executor.kt:84)
	at kotlin.coroutines.jvm.internal.BaseContinuationImpl.resumeWith(ContinuationImpl.kt:33)
	at kotlinx.coroutines.DispatchedTask.run(DispatchedTask.kt:106)
	at kotlinx.coroutines.EventLoopImplBase.processNextEvent(EventLoop.common.kt:279)
	at kotlinx.coroutines.BlockingCoroutine.joinBlocking(Builders.kt:85)
	at kotlinx.coroutines.BuildersKt__BuildersKt.runBlocking(Builders.kt:59)
	at kotlinx.coroutines.BuildersKt.runBlocking(Unknown Source)
	at kotlinx.coroutines.BuildersKt__BuildersKt.runBlocking$default(Builders.kt:38)
	at kotlinx.coroutines.BuildersKt.runBlocking$default(Unknown Source)
	at org.spekframework.spek2.runtime.TaskRunner$runTask$1.run(executors.kt:26)
	at java.util.concurrent.Executors$RunnableAdapter.call(Executors.java:511)
	at java.util.concurrent.FutureTask.run(FutureTask.java:266)
	at java.util.concurrent.ThreadPoolExecutor.runWorker(ThreadPoolExecutor.java:1149)
	at java.util.concurrent.ThreadPoolExecutor$Worker.run(ThreadPoolExecutor.java:624)
	at java.lang.Thread.run(Thread.java:748)
</failure>
  </testcase>
  <testcase name="[Latihan 5] - sum function should be return 107 if valueA is 100 and valueB is 7" classname="ExamTest" time="0.001">
    <failure message="org.opentest4j.AssertionFailedError: expected: &lt;true&gt; but was: &lt;false&gt;" type="org.opentest4j.AssertionFailedError">org.opentest4j.AssertionFailedError: expected: &lt;true&gt; but was: &lt;false&gt;
	at org.junit.jupiter.api.AssertionUtils.fail(AssertionUtils.java:55)
	at org.junit.jupiter.api.AssertTrue.assertTrue(AssertTrue.java:40)
	at org.junit.jupiter.api.AssertTrue.assertTrue(AssertTrue.java:35)
	at org.junit.jupiter.api.Assertions.assertTrue(Assertions.java:179)
	at ExamTest$1$1$5$3$1.invokeSuspend(ExamTest.kt:143)
	at kotlin.coroutines.jvm.internal.BaseContinuationImpl.resumeWith(ContinuationImpl.kt:33)
	at kotlinx.coroutines.DispatchedTask.run(DispatchedTask.kt:106)
	at kotlinx.coroutines.EventLoopImplBase.processNextEvent(EventLoop.common.kt:279)
	at kotlinx.coroutines.BlockingCoroutine.joinBlocking(Builders.kt:85)
	at kotlinx.coroutines.BuildersKt__BuildersKt.runBlocking(Builders.kt:59)
	at kotlinx.coroutines.BuildersKt.runBlocking(Unknown Source)
	at kotlinx.coroutines.BuildersKt__BuildersKt.runBlocking$default(Builders.kt:38)
	at kotlinx.coroutines.BuildersKt.runBlocking$default(Unknown Source)
	at ExamTest$1$1$5$3.invoke(ExamTest.kt:141)
	at ExamTest$1$1$5$3.invoke(ExamTest.kt:140)
	at org.spekframework.spek2.runtime.scope.TestScopeImpl.execute(scopes.kt:136)
	at org.spekframework.spek2.runtime.Executor$execute$result$2$exception$1$job$1.invokeSuspend(Executor.kt:84)
	at kotlin.coroutines.jvm.internal.BaseContinuationImpl.resumeWith(ContinuationImpl.kt:33)
	at kotlinx.coroutines.DispatchedTask.run(DispatchedTask.kt:106)
	at kotlinx.coroutines.EventLoopImplBase.processNextEvent(EventLoop.common.kt:279)
	at kotlinx.coroutines.BlockingCoroutine.joinBlocking(Builders.kt:85)
	at kotlinx.coroutines.BuildersKt__BuildersKt.runBlocking(Builders.kt:59)
	at kotlinx.coroutines.BuildersKt.runBlocking(Unknown Source)
	at kotlinx.coroutines.BuildersKt__BuildersKt.runBlocking$default(Builders.kt:38)
	at kotlinx.coroutines.BuildersKt.runBlocking$default(Unknown Source)
	at org.spekframework.spek2.runtime.TaskRunner$runTask$1.run(executors.kt:26)
	at java.util.concurrent.Executors$RunnableAdapter.call(Executors.java:511)
	at java.util.concurrent.FutureTask.run(FutureTask.java:266)
	at java.util.concurrent.ThreadPoolExecutor.runWorker(ThreadPoolExecutor.java:1149)
	at java.util.concurrent.ThreadPoolExecutor$Worker.run(ThreadPoolExecutor.java:624)
	at java.lang.Thread.run(Thread.java:748)
</failure>
  </testcase>
  <testcase name="[Latihan 5] - execution time of multiple function should be more than 2s" classname="ExamTest" time="0.001">
    <failure message="org.opentest4j.AssertionFailedError: expected: &lt;true&gt; but was: &lt;false&gt;" type="org.opentest4j.AssertionFailedError">org.opentest4j.AssertionFailedError: expected: &lt;true&gt; but was: &lt;false&gt;
	at org.junit.jupiter.api.AssertionUtils.fail(AssertionUtils.java:55)
	at org.junit.jupiter.api.AssertTrue.assertTrue(AssertTrue.java:40)
	at org.junit.jupiter.api.AssertTrue.assertTrue(AssertTrue.java:35)
	at org.junit.jupiter.api.Assertions.assertTrue(Assertions.java:179)
	at ExamTest$1$1$5$4$1.invokeSuspend(ExamTest.kt:153)
	at kotlin.coroutines.jvm.internal.BaseContinuationImpl.resumeWith(ContinuationImpl.kt:33)
	at kotlinx.coroutines.DispatchedTask.run(DispatchedTask.kt:106)
	at kotlinx.coroutines.EventLoopImplBase.processNextEvent(EventLoop.common.kt:279)
	at kotlinx.coroutines.BlockingCoroutine.joinBlocking(Builders.kt:85)
	at kotlinx.coroutines.BuildersKt__BuildersKt.runBlocking(Builders.kt:59)
	at kotlinx.coroutines.BuildersKt.runBlocking(Unknown Source)
	at kotlinx.coroutines.BuildersKt__BuildersKt.runBlocking$default(Builders.kt:38)
	at kotlinx.coroutines.BuildersKt.runBlocking$default(Unknown Source)
	at ExamTest$1$1$5$4.invoke(ExamTest.kt:148)
	at ExamTest$1$1$5$4.invoke(ExamTest.kt:147)
	at org.spekframework.spek2.runtime.scope.TestScopeImpl.execute(scopes.kt:136)
	at org.spekframework.spek2.runtime.Executor$execute$result$2$exception$1$job$1.invokeSuspend(Executor.kt:84)
	at kotlin.coroutines.jvm.internal.BaseContinuationImpl.resumeWith(ContinuationImpl.kt:33)
	at kotlinx.coroutines.DispatchedTask.run(DispatchedTask.kt:106)
	at kotlinx.coroutines.EventLoopImplBase.processNextEvent(EventLoop.common.kt:279)
	at kotlinx.coroutines.BlockingCoroutine.joinBlocking(Builders.kt:85)
	at kotlinx.coroutines.BuildersKt__BuildersKt.runBlocking(Builders.kt:59)
	at kotlinx.coroutines.BuildersKt.runBlocking(Unknown Source)
	at kotlinx.coroutines.BuildersKt__BuildersKt.runBlocking$default(Builders.kt:38)
	at kotlinx.coroutines.BuildersKt.runBlocking$default(Unknown Source)
	at org.spekframework.spek2.runtime.TaskRunner$runTask$1.run(executors.kt:26)
	at java.util.concurrent.Executors$RunnableAdapter.call(Executors.java:511)
	at java.util.concurrent.FutureTask.run(FutureTask.java:266)
	at java.util.concurrent.ThreadPoolExecutor.runWorker(ThreadPoolExecutor.java:1149)
	at java.util.concurrent.ThreadPoolExecutor$Worker.run(ThreadPoolExecutor.java:624)
	at java.lang.Thread.run(Thread.java:748)
</failure>
  </testcase>
  <testcase name="[Latihan 5] - multiple function should be return 36 if valueA is 6 and valueB is 6" classname="ExamTest" time="0.001">
    <failure message="org.opentest4j.AssertionFailedError: expected: &lt;true&gt; but was: &lt;false&gt;" type="org.opentest4j.AssertionFailedError">org.opentest4j.AssertionFailedError: expected: &lt;true&gt; but was: &lt;false&gt;
	at org.junit.jupiter.api.AssertionUtils.fail(AssertionUtils.java:55)
	at org.junit.jupiter.api.AssertTrue.assertTrue(AssertTrue.java:40)
	at org.junit.jupiter.api.AssertTrue.assertTrue(AssertTrue.java:35)
	at org.junit.jupiter.api.Assertions.assertTrue(Assertions.java:179)
	at ExamTest$1$1$5$5$1.invokeSuspend(ExamTest.kt:160)
	at kotlin.coroutines.jvm.internal.BaseContinuationImpl.resumeWith(ContinuationImpl.kt:33)
	at kotlinx.coroutines.DispatchedTask.run(DispatchedTask.kt:106)
	at kotlinx.coroutines.EventLoopImplBase.processNextEvent(EventLoop.common.kt:279)
	at kotlinx.coroutines.BlockingCoroutine.joinBlocking(Builders.kt:85)
	at kotlinx.coroutines.BuildersKt__BuildersKt.runBlocking(Builders.kt:59)
	at kotlinx.coroutines.BuildersKt.runBlocking(Unknown Source)
	at kotlinx.coroutines.BuildersKt__BuildersKt.runBlocking$default(Builders.kt:38)
	at kotlinx.coroutines.BuildersKt.runBlocking$default(Unknown Source)
	at ExamTest$1$1$5$5.invoke(ExamTest.kt:158)
	at ExamTest$1$1$5$5.invoke(ExamTest.kt:157)
	at org.spekframework.spek2.runtime.scope.TestScopeImpl.execute(scopes.kt:136)
	at org.spekframework.spek2.runtime.Executor$execute$result$2$exception$1$job$1.invokeSuspend(Executor.kt:84)
	at kotlin.coroutines.jvm.internal.BaseContinuationImpl.resumeWith(ContinuationImpl.kt:33)
	at kotlinx.coroutines.DispatchedTask.run(DispatchedTask.kt:106)
	at kotlinx.coroutines.EventLoopImplBase.processNextEvent(EventLoop.common.kt:279)
	at kotlinx.coroutines.BlockingCoroutine.joinBlocking(Builders.kt:85)
	at kotlinx.coroutines.BuildersKt__BuildersKt.runBlocking(Builders.kt:59)
	at kotlinx.coroutines.BuildersKt.runBlocking(Unknown Source)
	at kotlinx.coroutines.BuildersKt__BuildersKt.runBlocking$default(Builders.kt:38)
	at kotlinx.coroutines.BuildersKt.runBlocking$default(Unknown Source)
	at org.spekframework.spek2.runtime.TaskRunner$runTask$1.run(executors.kt:26)
	at java.util.concurrent.Executors$RunnableAdapter.call(Executors.java:511)
	at java.util.concurrent.FutureTask.run(FutureTask.java:266)
	at java.util.concurrent.ThreadPoolExecutor.runWorker(ThreadPoolExecutor.java:1149)
	at java.util.concurrent.ThreadPoolExecutor$Worker.run(ThreadPoolExecutor.java:624)
	at java.lang.Thread.run(Thread.java:748)
</failure>
  </testcase>
  <testcase name="[Latihan 5] - multiple function should be return 25 if valueA is 5 and valueB is 5" classname="ExamTest" time="0.002">
    <failure message="org.opentest4j.AssertionFailedError: expected: &lt;true&gt; but was: &lt;false&gt;" type="org.opentest4j.AssertionFailedError">org.opentest4j.AssertionFailedError: expected: &lt;true&gt; but was: &lt;false&gt;
	at org.junit.jupiter.api.AssertionUtils.fail(AssertionUtils.java:55)
	at org.junit.jupiter.api.AssertTrue.assertTrue(AssertTrue.java:40)
	at org.junit.jupiter.api.AssertTrue.assertTrue(AssertTrue.java:35)
	at org.junit.jupiter.api.Assertions.assertTrue(Assertions.java:179)
	at ExamTest$1$1$5$6$1.invokeSuspend(ExamTest.kt:167)
	at kotlin.coroutines.jvm.internal.BaseContinuationImpl.resumeWith(ContinuationImpl.kt:33)
	at kotlinx.coroutines.DispatchedTask.run(DispatchedTask.kt:106)
	at kotlinx.coroutines.EventLoopImplBase.processNextEvent(EventLoop.common.kt:279)
	at kotlinx.coroutines.BlockingCoroutine.joinBlocking(Builders.kt:85)
	at kotlinx.coroutines.BuildersKt__BuildersKt.runBlocking(Builders.kt:59)
	at kotlinx.coroutines.BuildersKt.runBlocking(Unknown Source)
	at kotlinx.coroutines.BuildersKt__BuildersKt.runBlocking$default(Builders.kt:38)
	at kotlinx.coroutines.BuildersKt.runBlocking$default(Unknown Source)
	at ExamTest$1$1$5$6.invoke(ExamTest.kt:165)
	at ExamTest$1$1$5$6.invoke(ExamTest.kt:164)
	at org.spekframework.spek2.runtime.scope.TestScopeImpl.execute(scopes.kt:136)
	at org.spekframework.spek2.runtime.Executor$execute$result$2$exception$1$job$1.invokeSuspend(Executor.kt:84)
	at kotlin.coroutines.jvm.internal.BaseContinuationImpl.resumeWith(ContinuationImpl.kt:33)
	at kotlinx.coroutines.DispatchedTask.run(DispatchedTask.kt:106)
	at kotlinx.coroutines.EventLoopImplBase.processNextEvent(EventLoop.common.kt:279)
	at kotlinx.coroutines.BlockingCoroutine.joinBlocking(Builders.kt:85)
	at kotlinx.coroutines.BuildersKt__BuildersKt.runBlocking(Builders.kt:59)
	at kotlinx.coroutines.BuildersKt.runBlocking(Unknown Source)
	at kotlinx.coroutines.BuildersKt__BuildersKt.runBlocking$default(Builders.kt:38)
	at kotlinx.coroutines.BuildersKt.runBlocking$default(Unknown Source)
	at org.spekframework.spek2.runtime.TaskRunner$runTask$1.run(executors.kt:26)
	at java.util.concurrent.Executors$RunnableAdapter.call(Executors.java:511)
	at java.util.concurrent.FutureTask.run(FutureTask.java:266)
	at java.util.concurrent.ThreadPoolExecutor.runWorker(ThreadPoolExecutor.java:1149)
	at java.util.concurrent.ThreadPoolExecutor$Worker.run(ThreadPoolExecutor.java:624)
	at java.lang.Thread.run(Thread.java:748)
</failure>
  </testcase>
  <system-out><![CDATA[]]></system-out>
  <system-err><![CDATA[]]></system-err>
</testsuite>
